 * Running on http://0.0.0.0:8080/ (Press CTRL+C to quit)
59.172.176.231 - - [07/Oct/2016 18:07:12] "GET / HTTP/1.1" 200 -
111.248.126.222 - - [07/Oct/2016 18:28:55] "CONNECT 163mx03.mxmail.netease.com:25 HTTP/1.0" 404 -
222.186.56.244 - - [07/Oct/2016 19:03:51] "GET /manager/html HTTP/1.1" 404 -
180.153.0.12 - - [07/Oct/2016 19:14:46] "GET / HTTP/1.0" 200 -
115.239.228.202 - - [07/Oct/2016 20:02:43] "GET http://zc.qq.com/cgi-bin/common/attr?id=260714&r=0.2215867301408667 HTTP/1.1" 404 -
59.172.176.231 - - [07/Oct/2016 20:23:22] "GET / HTTP/1.1" 200 -
59.172.176.231 - - [07/Oct/2016 20:23:24] "GET /favicon.ico HTTP/1.1" 404 -
59.172.176.231 - - [07/Oct/2016 20:43:28] "GET / HTTP/1.1" 200 -
Traceback (most recent call last):
  File "/home/ubuntu/pytest/microblog/run.py", line 2, in <module>
    from app import app
  File "/home/ubuntu/pytest/microblog/app/__init__.py", line 6, in <module>
    from app import views
  File "/home/ubuntu/pytest/microblog/app/views.py", line 32
    return render_template('/showlove/love.html')
                                                ^
TabError: inconsistent use of tabs and spaces in indentation
Traceback (most recent call last):
  File "/home/ubuntu/pytest/microblog/run.py", line 2, in <module>
    from app import app
  File "/home/ubuntu/pytest/microblog/app/__init__.py", line 6, in <module>
    from app import views
  File "/home/ubuntu/pytest/microblog/app/views.py", line 32
    return render_template('/showlove/love.html')
                                                ^
TabError: inconsistent use of tabs and spaces in indentation
Traceback (most recent call last):
  File "/home/ubuntu/pytest/microblog/run.py", line 2, in <module>
    from app import app
  File "/home/ubuntu/pytest/microblog/app/__init__.py", line 6, in <module>
    from app import views
  File "/home/ubuntu/pytest/microblog/app/views.py", line 32
    return render_template('/showlove/love.html')
                                                ^
TabError: inconsistent use of tabs and spaces in indentation
Traceback (most recent call last):
  File "/home/ubuntu/pytest/microblog/run.py", line 2, in <module>
    from app import app
  File "/home/ubuntu/pytest/microblog/app/__init__.py", line 6, in <module>
    from app import views
  File "/home/ubuntu/pytest/microblog/app/views.py", line 32
    return render_template('/showlove/love.html')
                                                ^
TabError: inconsistent use of tabs and spaces in indentation
Traceback (most recent call last):
  File "/home/ubuntu/pytest/microblog/run.py", line 2, in <module>
    from app import app
  File "/home/ubuntu/pytest/microblog/app/__init__.py", line 6, in <module>
    from app import views
  File "/home/ubuntu/pytest/microblog/app/views.py", line 32
    return render_template('/showlove/love.html')
                                                ^
TabError: inconsistent use of tabs and spaces in indentation
Traceback (most recent call last):
  File "/home/ubuntu/pytest/microblog/run.py", line 2, in <module>
    from app import app
  File "/home/ubuntu/pytest/microblog/app/__init__.py", line 6, in <module>
    from app import views
  File "/home/ubuntu/pytest/microblog/app/views.py", line 32
    return render_template('/showlove/love.html')
                                                ^
TabError: inconsistent use of tabs and spaces in indentation
Traceback (most recent call last):
  File "/home/ubuntu/pytest/microblog/run.py", line 2, in <module>
    from app import app
  File "/home/ubuntu/pytest/microblog/app/__init__.py", line 6, in <module>
    from app import views
  File "/home/ubuntu/pytest/microblog/app/views.py", line 32
    return render_template('/showlove/love.html')
                                                ^
TabError: inconsistent use of tabs and spaces in indentation
Traceback (most recent call last):
  File "/home/ubuntu/pytest/microblog/run.py", line 2, in <module>
    from app import app
  File "/home/ubuntu/pytest/microblog/app/__init__.py", line 6, in <module>
    from app import views
  File "/home/ubuntu/pytest/microblog/app/views.py", line 32
    return render_template('/showlove/love.html')
                                                ^
TabError: inconsistent use of tabs and spaces in indentation
 * Running on http://0.0.0.0:8080/ (Press CTRL+C to quit)
59.172.176.231 - - [07/Oct/2016 20:52:59] "GET / HTTP/1.1" 200 -
59.172.176.231 - - [07/Oct/2016 20:52:59] "GET /zfbcdn.js HTTP/1.1" 200 -
59.172.176.231 - - [07/Oct/2016 20:53:00] "GET /static/favicon.ico HTTP/1.1" 200 -
59.172.176.231 - - [07/Oct/2016 20:53:07] "GET /jump HTTP/1.1" 200 -
59.172.176.231 - - [07/Oct/2016 20:53:20] "GET /love HTTP/1.1" 200 -
59.172.176.231 - - [07/Oct/2016 20:53:20] "GET /js/prefixfree.min.js HTTP/1.1" 404 -
59.172.176.231 - - [07/Oct/2016 20:53:21] "GET /follow.js HTTP/1.1" 404 -
59.172.176.231 - - [07/Oct/2016 20:53:21] "GET /js/jquery.lettering.js HTTP/1.1" 404 -
59.172.176.231 - - [07/Oct/2016 20:53:21] "GET /js/index.js HTTP/1.1" 404 -
59.172.176.231 - - [07/Oct/2016 20:53:21] "GET /js/jquery.js HTTP/1.1" 404 -
59.172.176.231 - - [07/Oct/2016 20:53:21] "GET /js/jquery.lettering.js HTTP/1.1" 404 -
59.172.176.231 - - [07/Oct/2016 20:53:21] "GET /js/index.js HTTP/1.1" 404 -
59.172.176.231 - - [07/Oct/2016 20:53:29] "GET /login HTTP/1.1" 200 -
59.172.176.231 - - [07/Oct/2016 20:53:43] "POST /user HTTP/1.1" 200 -
59.172.176.6 - - [07/Oct/2016 20:55:57] "GET / HTTP/1.1" 200 -
59.172.176.6 - - [07/Oct/2016 20:55:57] "GET /zfbcdn.js HTTP/1.1" 200 -
59.172.176.6 - - [07/Oct/2016 20:55:57] "GET /static/favicon.ico HTTP/1.1" 200 -
112.65.193.13 - - [07/Oct/2016 20:56:07] "GET /jump HTTP/1.1" 200 -
101.226.66.192 - - [07/Oct/2016 20:56:29] "GET /login HTTP/1.1" 200 -
59.172.176.6 - - [07/Oct/2016 20:56:42] "GET /love HTTP/1.1" 200 -
59.172.176.6 - - [07/Oct/2016 20:56:42] "GET /js/prefixfree.min.js HTTP/1.1" 404 -
59.172.176.6 - - [07/Oct/2016 20:56:42] "GET /js/jquery.js HTTP/1.1" 404 -
59.172.176.6 - - [07/Oct/2016 20:56:42] "GET /follow.js HTTP/1.1" 404 -
59.172.176.6 - - [07/Oct/2016 20:56:42] "GET /gg_bd_ad_720x90.js HTTP/1.1" 404 -
59.172.176.6 - - [07/Oct/2016 20:56:42] "GET /js/jquery.lettering.js HTTP/1.1" 404 -
59.172.176.6 - - [07/Oct/2016 20:56:42] "GET /js/index.js HTTP/1.1" 404 -
59.172.176.6 - - [07/Oct/2016 20:56:43] "GET /favicon.ico HTTP/1.1" 404 -
59.172.176.6 - - [07/Oct/2016 20:56:58] "GET /login HTTP/1.1" 200 -
59.172.176.6 - - [07/Oct/2016 20:56:58] "GET /favicon.ico HTTP/1.1" 404 -
59.172.176.6 - - [07/Oct/2016 20:57:18] "POST /user HTTP/1.1" 200 -
59.172.176.6 - - [07/Oct/2016 20:57:18] "GET /favicon.ico HTTP/1.1" 404 -
59.172.176.6 - - [07/Oct/2016 20:57:28] "GET /favicon.ico HTTP/1.1" 404 -
59.172.176.231 - - [07/Oct/2016 21:05:01] "GET / HTTP/1.1" 200 -
59.172.176.231 - - [07/Oct/2016 21:05:01] "GET /zfbcdn.js HTTP/1.1" 200 -
59.172.176.231 - - [07/Oct/2016 21:05:02] "GET /static/favicon.ico HTTP/1.1" 200 -
111.196.172.115 - - [07/Oct/2016 21:07:53] "CONNECT search.yahoo.com:443 HTTP/1.1" 404 -
182.254.154.72 - - [07/Oct/2016 22:09:18] "GET http://115.159.79.85/check_proxy.php HTTP/1.1" 404 -
59.172.176.231 - - [07/Oct/2016 23:03:17] "GET / HTTP/1.1" 200 -
59.172.176.231 - - [07/Oct/2016 23:03:17] "GET /zfbcdn.js HTTP/1.1" 200 -
 * Running on http://0.0.0.0:8080/ (Press CTRL+C to quit)
[2016-10-07 23:35:55,223] ERROR in app: Exception on / [GET]
Traceback (most recent call last):
  File "/usr/local/lib/python3.4/dist-packages/flask/app.py", line 1988, in wsgi_app
    response = self.full_dispatch_request()
  File "/usr/local/lib/python3.4/dist-packages/flask/app.py", line 1641, in full_dispatch_request
    rv = self.handle_user_exception(e)
  File "/usr/local/lib/python3.4/dist-packages/flask/app.py", line 1544, in handle_user_exception
    reraise(exc_type, exc_value, tb)
  File "/usr/local/lib/python3.4/dist-packages/flask/_compat.py", line 33, in reraise
    raise value
  File "/usr/local/lib/python3.4/dist-packages/flask/app.py", line 1639, in full_dispatch_request
    rv = self.dispatch_request()
  File "/usr/local/lib/python3.4/dist-packages/flask/app.py", line 1625, in dispatch_request
    return self.view_functions[rule.endpoint](**req.view_args)
  File "/home/ubuntu/pytest/microblog/app/views.py", line 21, in index
    f.write(request.remote_addr+"\t"+time.strftime("%Y-%m-%d %H:%M:%S",time.localtime())+"\u67e5\u770b\u4e3b\u9875"+"\n")
UnicodeEncodeError: 'ascii' codec can't encode characters in position 34-37: ordinal not in range(128)
59.172.176.231 - - [07/Oct/2016 23:35:56] "GET / HTTP/1.1" 500 -
[2016-10-08 00:26:33,370] ERROR in app: Exception on / [GET]
Traceback (most recent call last):
  File "/usr/local/lib/python3.4/dist-packages/flask/app.py", line 1988, in wsgi_app
    response = self.full_dispatch_request()
  File "/usr/local/lib/python3.4/dist-packages/flask/app.py", line 1641, in full_dispatch_request
    rv = self.handle_user_exception(e)
  File "/usr/local/lib/python3.4/dist-packages/flask/app.py", line 1544, in handle_user_exception
    reraise(exc_type, exc_value, tb)
  File "/usr/local/lib/python3.4/dist-packages/flask/_compat.py", line 33, in reraise
    raise value
  File "/usr/local/lib/python3.4/dist-packages/flask/app.py", line 1639, in full_dispatch_request
    rv = self.dispatch_request()
  File "/usr/local/lib/python3.4/dist-packages/flask/app.py", line 1625, in dispatch_request
    return self.view_functions[rule.endpoint](**req.view_args)
  File "/home/ubuntu/pytest/microblog/app/views.py", line 21, in index
    f.write(request.remote_addr+"\t"+time.strftime("%Y-%m-%d %H:%M:%S",time.localtime())+"\u67e5\u770b\u4e3b\u9875"+"\n")
UnicodeEncodeError: 'ascii' codec can't encode characters in position 34-37: ordinal not in range(128)
59.172.176.231 - - [08/Oct/2016 00:26:33] "GET / HTTP/1.1" 500 -
[2016-10-08 00:26:33,372] ERROR in app: Exception on / [GET]
Traceback (most recent call last):
  File "/usr/local/lib/python3.4/dist-packages/flask/app.py", line 1988, in wsgi_app
    response = self.full_dispatch_request()
  File "/usr/local/lib/python3.4/dist-packages/flask/app.py", line 1641, in full_dispatch_request
    rv = self.handle_user_exception(e)
  File "/usr/local/lib/python3.4/dist-packages/flask/app.py", line 1544, in handle_user_exception
    reraise(exc_type, exc_value, tb)
  File "/usr/local/lib/python3.4/dist-packages/flask/_compat.py", line 33, in reraise
    raise value
  File "/usr/local/lib/python3.4/dist-packages/flask/app.py", line 1639, in full_dispatch_request
    rv = self.dispatch_request()
  File "/usr/local/lib/python3.4/dist-packages/flask/app.py", line 1625, in dispatch_request
    return self.view_functions[rule.endpoint](**req.view_args)
  File "/home/ubuntu/pytest/microblog/app/views.py", line 21, in index
    f.write(request.remote_addr+"\t"+time.strftime("%Y-%m-%d %H:%M:%S",time.localtime())+"\u67e5\u770b\u4e3b\u9875"+"\n")
UnicodeEncodeError: 'ascii' codec can't encode characters in position 34-37: ordinal not in range(128)
59.172.176.231 - - [08/Oct/2016 00:26:33] "GET / HTTP/1.1" 500 -
[2016-10-08 00:29:31,036] ERROR in app: Exception on / [GET]
Traceback (most recent call last):
  File "/usr/local/lib/python3.4/dist-packages/flask/app.py", line 1988, in wsgi_app
    response = self.full_dispatch_request()
  File "/usr/local/lib/python3.4/dist-packages/flask/app.py", line 1641, in full_dispatch_request
    rv = self.handle_user_exception(e)
  File "/usr/local/lib/python3.4/dist-packages/flask/app.py", line 1544, in handle_user_exception
    reraise(exc_type, exc_value, tb)
  File "/usr/local/lib/python3.4/dist-packages/flask/_compat.py", line 33, in reraise
    raise value
  File "/usr/local/lib/python3.4/dist-packages/flask/app.py", line 1639, in full_dispatch_request
    rv = self.dispatch_request()
  File "/usr/local/lib/python3.4/dist-packages/flask/app.py", line 1625, in dispatch_request
    return self.view_functions[rule.endpoint](**req.view_args)
  File "/home/ubuntu/pytest/microblog/app/views.py", line 21, in index
    f.write(request.remote_addr+"\t"+time.strftime("%Y-%m-%d %H:%M:%S",time.localtime())+"\u67e5\u770b\u4e3b\u9875"+"\n")
UnicodeEncodeError: 'ascii' codec can't encode characters in position 34-37: ordinal not in range(128)
59.172.176.231 - - [08/Oct/2016 00:29:31] "GET / HTTP/1.1" 500 -
[uWSGI] getting INI configuration from /home/ubuntu/pytest/microblog/blog_uwsgi.ini
[uWSGI] getting INI configuration from /home/ubuntu/pytest/microblog/blog_uwsgi.ini
[uWSGI] getting INI configuration from /home/ubuntu/pytest/microblog/blog_uwsgi.ini
[uWSGI] getting INI configuration from /home/ubuntu/pytest/microblog/blog_uwsgi.ini
[uWSGI] getting INI configuration from /home/ubuntu/pytest/microblog/blog_uwsgi.ini
[uWSGI] getting INI configuration from /home/ubuntu/pytest/microblog/blog_uwsgi.ini
[uWSGI] getting INI configuration from /home/ubuntu/pytest/microblog/blog_uwsgi.ini
[uWSGI] getting INI configuration from /home/ubuntu/pytest/microblog/blog_uwsgi.ini
[uWSGI] getting INI configuration from /home/ubuntu/pytest/microblog/blog_uwsgi.ini
[uWSGI] getting INI configuration from /home/ubuntu/pytest/microblog/blog_uwsgi.ini
[uWSGI] getting INI configuration from /home/ubuntu/pytest/microblog/blog_uwsgi.ini
[uWSGI] getting INI configuration from /home/ubuntu/pytest/microblog/blog_uwsgi.ini
[uWSGI] getting INI configuration from /home/ubuntu/pytest/microblog/blog_uwsgi.ini
[uWSGI] getting INI configuration from /home/ubuntu/pytest/microblog/blog_uwsgi.ini
[uWSGI] getting INI configuration from /home/ubuntu/pytest/microblog/blog_uwsgi.ini
Traceback (most recent call last):
  File "/home/ubuntu/pytest/microblog/run.py", line 2, in <module>
    from app import app
  File "/home/ubuntu/pytest/microblog/app/__init__.py", line 6, in <module>
    from app import views
  File "/home/ubuntu/pytest/microblog/app/views.py", line 32
    return render_template('/showlove/love.html')
                                                ^
TabError: inconsistent use of tabs and spaces in indentation
Traceback (most recent call last):
  File "/home/ubuntu/pytest/microblog/run.py", line 2, in <module>
    from app import app
  File "/home/ubuntu/pytest/microblog/app/__init__.py", line 6, in <module>
    from app import views
  File "/home/ubuntu/pytest/microblog/app/views.py", line 32
    return render_template('/showlove/love.html')
                                                ^
TabError: inconsistent use of tabs and spaces in indentation
Traceback (most recent call last):
  File "/home/ubuntu/pytest/microblog/run.py", line 2, in <module>
    from app import app
  File "/home/ubuntu/pytest/microblog/app/__init__.py", line 6, in <module>
    from app import views
  File "/home/ubuntu/pytest/microblog/app/views.py", line 32
    return render_template('/showlove/love.html')
                                                ^
TabError: inconsistent use of tabs and spaces in indentation
Traceback (most recent call last):
  File "/home/ubuntu/pytest/microblog/run.py", line 2, in <module>
    from app import app
  File "/home/ubuntu/pytest/microblog/app/__init__.py", line 6, in <module>
    from app import views
  File "/home/ubuntu/pytest/microblog/app/views.py", line 32
    return render_template('/showlove/love.html')
                                                ^
TabError: inconsistent use of tabs and spaces in indentation
Traceback (most recent call last):
  File "/home/ubuntu/pytest/microblog/run.py", line 2, in <module>
    from app import app
  File "/home/ubuntu/pytest/microblog/app/__init__.py", line 6, in <module>
    from app import views
  File "/home/ubuntu/pytest/microblog/app/views.py", line 32
    return render_template('/showlove/love.html')
                                                ^
TabError: inconsistent use of tabs and spaces in indentation
Traceback (most recent call last):
  File "/home/ubuntu/pytest/microblog/run.py", line 2, in <module>
    from app import app
  File "/home/ubuntu/pytest/microblog/app/__init__.py", line 6, in <module>
    from app import views
  File "/home/ubuntu/pytest/microblog/app/views.py", line 32
    return render_template('/showlove/love.html')
                                                ^
TabError: inconsistent use of tabs and spaces in indentation
Traceback (most recent call last):
  File "/home/ubuntu/pytest/microblog/run.py", line 2, in <module>
    from app import app
  File "/home/ubuntu/pytest/microblog/app/__init__.py", line 6, in <module>
    from app import views
  File "/home/ubuntu/pytest/microblog/app/views.py", line 32
    return render_template('/showlove/love.html')
                                                ^
TabError: inconsistent use of tabs and spaces in indentation
Traceback (most recent call last):
  File "/home/ubuntu/pytest/microblog/run.py", line 2, in <module>
    from app import app
  File "/home/ubuntu/pytest/microblog/app/__init__.py", line 6, in <module>
    from app import views
  File "/home/ubuntu/pytest/microblog/app/views.py", line 32
    return render_template('/showlove/love.html')
                                                ^
TabError: inconsistent use of tabs and spaces in indentation
